{
  "detail": "! Message=[Wrong number of records deleted (0).Deleted count=(0), Acknowledged=(True).\n ]   Error while deleting (test_csv_object_id), status=[exception] stderr=[\n ! Exception <class 'FileNotFoundError'> occurred while deleting job from filesystem, message=[[Errno 2] No such file or directory: '/app/data/test_csv_object_id-data'] \n! traceback=\nTraceback (most recent call last):\n  File \"./app/main.py\", line 309, in delete\n    shutil.rmtree(local_path,ignore_errors=False)\n  File \"/usr/local/lib/python3.7/shutil.py\", line 485, in rmtree\n    onerror(os.lstat, path, sys.exc_info())\n  File \"/usr/local/lib/python3.7/shutil.py\", line 483, in rmtree\n    orig_st = os.lstat(path)\nFileNotFoundError: [Errno 2] No such file or directory: '/app/data/test_csv_object_id-data'\n]",
  "stderr": "xxx"
}
